<?xml version="1.0" encoding="utf-8"?>
<!-- =================================================================================== -->
<!-- |    This document was autogenerated by xacro from kuka_table.urdf.xacro          | -->
<!-- |    EDITING THIS FILE BY HAND IS NOT RECOMMENDED                                 | -->
<!-- =================================================================================== -->
<robot name="KUKA">
  <material name="Kuka/DarkGrey">
    <color rgba="0.3 0.3 0.3 1.0"/>
  </material>
  <material name="Kuka/LightGrey">
    <color rgba="0.8 0.8 0.8 1.0"/>
  </material>
  <material name="Kuka/Red">
    <color rgba="0.3 0.3 0.3 1.0"/>
  </material>
  <material name="Kuka/Black">
    <color rgba="0 0 0 1.0"/>
  </material>
  <material name="Kuka/Orange">
    <color rgba="1.0 0.487 0 1.0"/>
  </material>
  <material name="Kuka/Silver">
    <color rgba="1.0 1.0 1.0 1.0"/>
  </material>
  <material name="Kuka/Grey">
    <color rgba="0.7 0.7 0.7 1.0"/>
  </material>
  <material name="Kuka/Blue">
    <color rgba="0.0 0.0 0.8 1.0"/>
  </material>
  <!-- reflex to stiffness -->
  <!-- List of Links -->
  <!-- Link 1 -->
  <link name="KUKA_base_link">
    <inertial>
      <mass value="2.0"/>
      <origin xyz="0 0 0.055"/>
      <inertia ixx="0.00381666666667" ixy="0" ixz="0" iyy="0.0036" iyz="0" izz="0.00381666666667"/>
    </inertial>
    <visual>
      <origin rpy="0 0 3.14159265359" xyz="0 0 0"/>
      <geometry>
        <mesh filename="package://kuka_description/meshes/base.STL"/>
      </geometry>
      <material name="Kuka/Orange"/>
    </visual>
    <collision>
      <origin rpy="0 0 3.14159265359" xyz="0 0 0.055"/>
      <geometry>
        <cylinder length="0.11" radius="0.0815"/>
      </geometry>
    </collision>
  </link>
  <!-- Link 2 -->
  <link name="KUKA_1_link">
    <inertial>
      <mass value="2.35"/>
      <origin rpy="0 0 0" xyz="0 -0.06 0.130"/>
      <inertia ixx="0.0160583333333" ixy="0" ixz="0" iyy="0.003525" iyz="0" izz="0.0139433333333"/>
    </inertial>
    <visual>
      <origin rpy="0 0 3.14159265359" xyz="0 0 -0.008"/>
      <geometry>
        <mesh filename="package://kuka_description/meshes/link_1.STL"/>
      </geometry>
      <material name="Kuka/Orange"/>
    </visual>
    <collision>
      <origin rpy="0 0 0" xyz="0 -0.03 0"/>
      <geometry>
        <sphere radius="0.077"/>
      </geometry>
    </collision>
    <collision>
      <origin rpy="0 0 0" xyz="0 0.05 0.2"/>
      <geometry>
        <sphere radius="0.077"/>
      </geometry>
    </collision>
    <collision>
      <origin rpy="-0.291 0 0" xyz="0 0.03 0.1"/>
      <geometry>
        <cylinder length="0.208" radius="0.077"/>
      </geometry>
    </collision>
  </link>
  <!-- Link 3 -->
  <link name="KUKA_2_link">
    <inertial>
      <mass value="2.35"/>
      <origin rpy="0 0 0" xyz="0 0.06 0.07"/>
      <inertia ixx="0.0160583333333" ixy="0" ixz="0" iyy="0.003525" iyz="0" izz="0.0139433333333"/>
    </inertial>
    <visual>
      <origin rpy="0 0 3.14159265359" xyz="0 0 0.0"/>
      <geometry>
        <mesh filename="package://kuka_description/meshes/link_2.STL"/>
      </geometry>
      <material name="Kuka/Orange"/>
    </visual>
    <collision>
      <origin rpy="0 0 0" xyz="0 0 0.2"/>
      <geometry>
        <sphere radius="0.077"/>
      </geometry>
    </collision>
    <collision>
      <origin rpy="0 0 0" xyz="0 -0.04 0.0"/>
      <geometry>
        <sphere radius="0.077"/>
      </geometry>
    </collision>
    <collision>
      <origin rpy="-0.291 0 0" xyz="0 -0.03 0.1"/>
      <geometry>
        <cylinder length="0.208" radius="0.077"/>
      </geometry>
    </collision>
  </link>
  <!-- Link 4 -->
  <link name="KUKA_3_link">
    <inertial>
      <mass value="2.35"/>
      <origin rpy="0 0 0" xyz="0 0.06 0.130"/>
      <inertia ixx="0.0160583333333" ixy="0" ixz="0" iyy="0.003525" iyz="0" izz="0.0139433333333"/>
    </inertial>
    <visual>
      <origin rpy="0 0 3.14159265359" xyz="0 0 -0.008"/>
      <geometry>
        <mesh filename="package://kuka_description/meshes/link_3.STL"/>
      </geometry>
      <material name="Kuka/Orange"/>
    </visual>
    <collision>
      <origin rpy="0 0 0" xyz="0 0 0.0"/>
      <geometry>
        <sphere radius="0.077"/>
      </geometry>
    </collision>
    <collision>
      <origin rpy="0 0 0" xyz="0 -0.06 0.2"/>
      <geometry>
        <sphere radius="0.077"/>
      </geometry>
    </collision>
    <collision>
      <origin rpy="0.291 0 0" xyz="0 -0.03 0.1"/>
      <geometry>
        <cylinder length="0.208" radius="0.077"/>
      </geometry>
    </collision>
  </link>
  <!-- Link 5 -->
  <link name="KUKA_4_link">
    <inertial>
      <mass value="2.35"/>
      <origin rpy="0 0 0" xyz="0 -0.06 0.07"/>
      <inertia ixx="0.0160583333333" ixy="0" ixz="0" iyy="0.003525" iyz="0" izz="0.0139433333333"/>
    </inertial>
    <visual>
      <origin rpy="0 0 3.14159265359" xyz="0 0 0"/>
      <geometry>
        <mesh filename="package://kuka_description/meshes/link_4.STL"/>
      </geometry>
      <material name="Kuka/Orange"/>
    </visual>
    <collision>
      <origin rpy="0 0 0" xyz="0 0.01 0.2"/>
      <geometry>
        <sphere radius="0.077"/>
      </geometry>
    </collision>
    <collision>
      <origin rpy="0 0 0" xyz="0 0.05 0.0"/>
      <geometry>
        <sphere radius="0.077"/>
      </geometry>
    </collision>
    <collision>
      <origin rpy="0.291 0 0" xyz="0 0.02 0.1"/>
      <geometry>
        <cylinder length="0.208" radius="0.077"/>
      </geometry>
    </collision>
  </link>
  <!-- Link 6 -->
  <link name="KUKA_5_link">
    <inertial>
      <mass value="2.35"/>
      <origin rpy="0 0 0" xyz="0 0 0.124"/>
      <inertia ixx="0.0148645333333" ixy="0" ixz="0" iyy="0.003525" iyz="0" izz="0.0127495333333"/>
    </inertial>
    <visual>
      <origin rpy="0 0 3.14159265359" xyz="0 0 -0.008"/>
      <geometry name="KUKA_5_geom">
        <mesh filename="package://kuka_description/meshes/link_5.STL"/>
      </geometry>
      <material name="Kuka/Orange"/>
    </visual>
    <collision>
      <origin rpy="0 0 0" xyz="0 0 0.0"/>
      <geometry>
        <sphere radius="0.07"/>
      </geometry>
    </collision>
    <collision>
      <origin rpy="0 0 0" xyz="0 0.04 0.19"/>
      <geometry>
        <sphere radius="0.07"/>
      </geometry>
    </collision>
    <collision>
      <origin rpy="-0.207 0 0" xyz="0 0.02 0.095"/>
      <geometry>
        <cylinder length="0.198" radius="0.07"/>
      </geometry>
    </collision>
  </link>
  <!-- Link 7 -->
  <link name="KUKA_6_link">
    <inertial>
      <mass value="1.1"/>
      <origin rpy="0 0 0" xyz="0 0 0.0625"/>
      <inertia ixx="0.00286458333333" ixy="0" ixz="0" iyy="0.00286458333333" iyz="0" izz="0.00286458333333"/>
    </inertial>
    <visual>
      <origin rpy="0 0 3.14159265359" xyz="0 0 0"/>
      <geometry>
        <mesh filename="package://kuka_description/meshes/link_6.STL"/>
      </geometry>
      <material name="Kuka/Grey"/>
    </visual>
    <collision>
      <origin rpy="0 0 3.14159265359" xyz="0 -0.01 0"/>
      <geometry>
        <sphere radius="0.08"/>
      </geometry>
    </collision>
  </link>
  <!-- Link 8 -->
  <link name="KUKA_7_link">
    <inertial>
      <mass value="2.6"/>
      <origin xyz="0 0 0.0025"/>
      <inertia ixx="0.00197166666667" ixy="0" ixz="0" iyy="0.00325" iyz="0" izz="0.00197166666667"/>
    </inertial>
    <visual>
      <origin rpy="0 0 0" xyz="0 0 -0.013"/>
      <geometry>
        <mesh filename="package://kuka_description/meshes/link_7.STL"/>
      </geometry>
      <material name="Kuka/DarkGrey"/>
    </visual>
    <collision>
      <origin rpy="0 0 0" xyz="0 0 0.0025"/>
      <geometry>
        <cylinder length="0.035" radius="0.043"/>
      </geometry>
    </collision>
    <collision>
      <origin rpy="0 0 0" xyz="0 0 0.19"/>
      <geometry>
        <cylinder length="0.15" radius="0.01"/>
      </geometry>
    </collision>
    <collision>
      <origin rpy="0 0 0" xyz="0 0 0.07"/>
      <geometry>
        <cylinder length="0.105" radius="0.045"/>
      </geometry>
    </collision>
  </link>
  <!-- Link 9 -->
  <!--<link name="${name}_8_link">
			<inertial>
				<mass value="${tip_mass}"/>
				<origin xyz="0 0 0.12"/>
				<xacro:cylinder_inertia_def radius="0.045" length="0.25" mass="${tip_mass}"/>
			</inertial>
			<visual>
				<origin xyz="0 0 -0.002" rpy="0 0 0"/>
				<geometry>
					<mesh filename="package://kuka_description/meshes/kuka_tip.STL"/>
				</geometry>
			<material name="Kuka/DarkGrey"/>
			</visual>
			<collision>
			<origin xyz="0 0 0.12" rpy="0 0 0"/>
			<geometry>
				<cylinder radius="0.045" length="0.25"/>
			</geometry>
			</collision>
		</link>-->
  <!-- List of Joints -->
  <!-- Second segment of the arm. Joint along z-axis -->
  <joint name="KUKA_a1_joint" type="revolute">
    <origin rpy="0 0 0" xyz="0 0 0.11"/>
    <axis xyz="0 0 1"/>
    <limit effort="176" lower="-2.96705972839" upper="2.96705972839" velocity="1.91986217719"/>
    <dynamics damping="1.0" friction="10.0"/>
    <parent link="KUKA_base_link"/>
    <child link="KUKA_1_link"/>
  </joint>
  <!-- 
	<joint name="${name}_a1_joint_stiffness" type="revolute">
			<axis xyz="0 0 1"/>
			<limit lower="${min_stiffness}" upper="${max_stiffness}" effort="0" velocity="${rate_stiffness}" />
			<safety_controller soft_lower_limit="${min_stiffness}" soft_upper_limit="${max_stiffness}" k_position="30" k_velocity="30"/>
			<parent link="${name}_base_link"/>
			<child link="${name}_1_link_dummy"/>
		</joint>
		<link name="${name}_1_link_dummy"/>

-->
  <!-- Third segment of the arm. Joint along y-axis -->
  <joint name="KUKA_a2_joint" type="revolute">
    <origin rpy="0 0 0" xyz="0 0 0.2005"/>
    <axis xyz="0 -1 0"/>
    <limit effort="176" lower="-2.09439510239" upper="2.09439510239" velocity="1.91986217719"/>
    <dynamics damping="1.0" friction="10.0"/>
    <parent link="KUKA_1_link"/>
    <child link="KUKA_2_link"/>
  </joint>
  <!--
        <joint name="${name}_a2_joint_stiffness" type="revolute">
			<axis xyz="0 0 1"/>
			<limit lower="${min_stiffness}" upper="${max_stiffness}" effort="0" velocity="${rate_stiffness}" />
			<safety_controller soft_lower_limit="${min_stiffness}" soft_upper_limit="${max_stiffness}" k_position="30" k_velocity="30"/>
			<parent link="${name}_1_link"/>
			<child link="${name}_2_link_dummy"/>
		</joint>
		<link name="${name}_2_link_dummy"/>
-->
  <!-- Fourth element of the arm. z-axis -->
  <joint name="KUKA_a3_joint" type="revolute">
    <origin rpy="0 0 0" xyz="0 0 0.20"/>
    <axis xyz="0 0 1"/>
    <limit effort="100" lower="-2.96705972839" upper="2.96705972839" velocity="2.23402144255"/>
    <dynamics damping="1.0" friction="10.0"/>
    <parent link="KUKA_2_link"/>
    <child link="KUKA_3_link"/>
  </joint>
  <!--
	<joint name="${name}_a3_joint_stiffness" type="revolute">
			<axis xyz="0 0 1"/>
			<limit lower="${min_stiffness}" upper="${max_stiffness}" effort="0" velocity="${rate_stiffness}" />
			<safety_controller soft_lower_limit="${min_stiffness}" soft_upper_limit="${max_stiffness}" k_position="30" k_velocity="30"/>
			<parent link="${name}_2_link"/>
			<child link="${name}_3_link_dummy"/>
		</joint>
		<link name="${name}_3_link_dummy"/>
-->
  <!-- fifth element of the arm. x-axis -->
  <joint name="KUKA_a4_joint" type="revolute">
    <origin rpy="0 0 0" xyz="0 0 0.2"/>
    <axis xyz="0 1 0"/>
    <limit effort="100" lower="-2.09439510239" upper="2.09439510239" velocity="2.23402144255"/>
    <dynamics damping="1.0" friction="10.0"/>
    <parent link="KUKA_3_link"/>
    <child link="KUKA_4_link"/>
  </joint>
  <!--
    <joint name="${name}_a3_joint_stiffness" type="revolute">
			<axis xyz="0 0 1"/>
			<limit lower="${min_stiffness}" upper="${max_stiffness}" effort="0" velocity="${rate_stiffness}" />
			<safety_controller soft_lower_limit="${min_stiffness}" soft_upper_limit="${max_stiffness}" k_position="30" k_velocity="30"/>
			<parent link="${name}_3_link"/>
			<child link="${name}_4_link_dummy"/>
		</joint>
		<link name="${name}_4_link_dummy"/>
-->
  <!-- Sixth element of the arm. z-axis -->
  <joint name="KUKA_a5_joint" type="revolute">
    <origin rpy="0 0 0" xyz="0 0 0.20"/>
    <axis xyz="0 0 1"/>
    <limit effort="100" lower="-2.96705972839" upper="2.96705972839" velocity="3.56047167407"/>
    <dynamics damping="1.0" friction="10.0"/>
    <parent link="KUKA_4_link"/>
    <child link="KUKA_5_link"/>
  </joint>
  <!--
	<joint name="${name}_a4_joint_stiffness" type="revolute">
			<axis xyz="0 0 1"/>
			<limit lower="${min_stiffness}" upper="${max_stiffness}" effort="0" velocity="${rate_stiffness}" />
			<safety_controller soft_lower_limit="${min_stiffness}" soft_upper_limit="${max_stiffness}" k_position="30" k_velocity="30"/>
			<parent link="${name}_4_link"/>
			<child link="${name}_5_link_dummy"/>
		</joint>
		<link name="${name}_5_link_dummy"/>
-->
  <!-- Seventh element of the arm. z-axis -->
  <joint name="KUKA_a6_joint" type="revolute">
    <origin rpy="0 0 0" xyz="0 0 0.19"/>
    <axis xyz="0 -1 0"/>
    <limit effort="38" lower="-2.09439510239" upper="2.09439510239" velocity="3.21140582367"/>
    <dynamics damping="1.0" friction="10.0"/>
    <parent link="KUKA_5_link"/>
    <child link="KUKA_6_link"/>
  </joint>
  <!--
	<joint name="${name}_a5_joint_stiffness" type="revolute">
			<axis xyz="0 0 1"/>
			<limit lower="${min_stiffness}" upper="${max_stiffness}" effort="0" velocity="${rate_stiffness}" />
			<safety_controller soft_lower_limit="${min_stiffness}" soft_upper_limit="${max_stiffness}" k_position="30" k_velocity="30"/>
			<parent link="${name}_5_link"/>
			<child link="${name}_6_link_dummy"/>
		</joint>
		<link name="${name}_6_link_dummy"/>
-->
  <!-- Eighth element of the arm. z-axis -->
  <joint name="KUKA_a7_joint" type="revolute">
    <origin rpy="0 0 0" xyz="0 0 0.06"/>
    <axis xyz="0 0 1"/>
    <limit effort="38" lower="-2.96705972839" upper="2.96705972839" velocity="3.21140582367"/>
    <dynamics damping="1.0" friction="10.0"/>
    <parent link="KUKA_6_link"/>
    <child link="KUKA_7_link"/>
  </joint>
  <!--
	<joint name="${name}_a6_joint_stiffness" type="revolute">
			<axis xyz="0 0 1"/>
			<limit lower="${min_stiffness}" upper="${max_stiffness}" effort="0" velocity="${rate_stiffness}" />
			<safety_controller soft_lower_limit="${min_stiffness}" soft_upper_limit="${max_stiffness}" k_position="30" k_velocity="30"/>
			<parent link="${name}_6_link"/>
			<child link="${name}_7_link_dummy"/>
		</joint>
		<link name="${name}_7_link_dummy"/>
-->
  <!-- Nineth element of the arm. z-axis -->
  <!-- 		<joint name="${name}_a8_joint" type="fixed">
			<origin xyz="0 0 0.02" rpy="0 0 0"/>
			<axis xyz="0 0 1"/>
			<limit effort="38" velocity="${velocity_scale * 184 * M_PI / 180}" />
			<dynamics friction="10.0" damping="1.0"/>
			<parent link="${name}_7_link"/>
			<child link="${name}_8_link"/>
		</joint>-->
  <!--
	<joint name="${name}_a7_joint_stiffness" type="fixed">
			<parent link="${name}_7_link"/>
			<child link="${name}_8_link_dummy"/>
		</joint>
		<link name="${name}_8_link_dummy"/>
-->
  <!--
		<gazebo>
			<plugin name="KUKA_lwr_hw_sim" filename="liblwr_hw_gazebo_plugin.so">
				<robotNamespace>/KUKA</robotNamespace>
			</plugin>
        </gazebo>
-->
  <gazebo>
    <plugin filename="libgazebo_ros_control.so" name="gazebo_ros_control">
      <robotNamespace>/KUKA</robotNamespace>
    </plugin>
  </gazebo>
  <gazebo reference="KUKA_base_link">
    <gravity>true</gravity>
    <material>Gazebo/Orange</material>
  </gazebo>
  <gazebo reference="KUKA_1_link">
    <gravity>true</gravity>
    <material>Gazebo/Orange</material>
  </gazebo>
  <gazebo reference="KUKA_2_link">
    <gravity>true</gravity>
    <material>Gazebo/Orange</material>
  </gazebo>
  <gazebo reference="KUKA_3_link">
    <gravity>true</gravity>
    <material>Gazebo/Orange</material>
  </gazebo>
  <gazebo reference="KUKA_4_link">
    <gravity>true</gravity>
    <material>Gazebo/Orange</material>
  </gazebo>
  <gazebo reference="KUKA_5_link">
    <gravity>true</gravity>
    <material>Gazebo/Orange</material>
  </gazebo>
  <gazebo reference="KUKA_6_link">
    <gravity>true</gravity>
    <material>Gazebo/Orange</material>
  </gazebo>
  <gazebo reference="KUKA_7_link">
    <gravity>true</gravity>
    <material>Gazebo/DarkGrey</material>
  </gazebo>
  <!--<gazebo reference="${name}_8_link">
			<gravity>true</gravity>
			<material>Gazebo/Grey</material>
		</gazebo>-->
  <transmission name="KUKA_a1_trans">
    <type>transmission_interface/SimpleTransmission</type>
    <joint name="KUKA_a1_joint">
      <hardwareInterface>hardware_interface/PositionJointInterface</hardwareInterface>
      <hardwareInterface>hardware_interface/EffortJointInterface</hardwareInterface>
    </joint>
    <actuator name="KUKA_a1_motor">
      <hardwareInterface>hardware_interface/PositionJointInterface</hardwareInterface>
      <hardwareInterface>hardware_interface/EffortJointInterface</hardwareInterface>
      <mechanicalReduction>1</mechanicalReduction>
    </actuator>
  </transmission>
  <transmission name="KUKA_a2_trans">
    <type>transmission_interface/SimpleTransmission</type>
    <joint name="KUKA_a2_joint">
      <hardwareInterface>hardware_interface/PositionJointInterface</hardwareInterface>
      <hardwareInterface>hardware_interface/EffortJointInterface</hardwareInterface>
    </joint>
    <actuator name="KUKA_a2_motor">
      <hardwareInterface>hardware_interface/PositionJointInterface</hardwareInterface>
      <hardwareInterface>hardware_interface/EffortJointInterface</hardwareInterface>
      <mechanicalReduction>1</mechanicalReduction>
    </actuator>
  </transmission>
  <transmission name="KUKA_a3_trans">
    <type>transmission_interface/SimpleTransmission</type>
    <joint name="KUKA_a3_joint">
      <hardwareInterface>hardware_interface/PositionJointInterface</hardwareInterface>
      <hardwareInterface>hardware_interface/EffortJointInterface</hardwareInterface>
    </joint>
    <actuator name="KUKA_a3_motor">
      <hardwareInterface>hardware_interface/PositionJointInterface</hardwareInterface>
      <hardwareInterface>hardware_interface/EffortJointInterface</hardwareInterface>
      <mechanicalReduction>1</mechanicalReduction>
    </actuator>
  </transmission>
  <transmission name="KUKA_a4_trans">
    <type>transmission_interface/SimpleTransmission</type>
    <joint name="KUKA_a4_joint">
      <hardwareInterface>hardware_interface/PositionJointInterface</hardwareInterface>
      <hardwareInterface>hardware_interface/EffortJointInterface</hardwareInterface>
    </joint>
    <actuator name="KUKA_a4_motor">
      <hardwareInterface>hardware_interface/PositionJointInterface</hardwareInterface>
      <hardwareInterface>hardware_interface/EffortJointInterface</hardwareInterface>
      <mechanicalReduction>1</mechanicalReduction>
    </actuator>
  </transmission>
  <transmission name="KUKA_a5_trans">
    <type>transmission_interface/SimpleTransmission</type>
    <joint name="KUKA_a5_joint">
      <hardwareInterface>hardware_interface/PositionJointInterface</hardwareInterface>
      <hardwareInterface>hardware_interface/EffortJointInterface</hardwareInterface>
    </joint>
    <actuator name="KUKA_a5_motor">
      <hardwareInterface>hardware_interface/PositionJointInterface</hardwareInterface>
      <hardwareInterface>hardware_interface/EffortJointInterface</hardwareInterface>
      <mechanicalReduction>1</mechanicalReduction>
    </actuator>
  </transmission>
  <transmission name="KUKA_a6_trans">
    <type>transmission_interface/SimpleTransmission</type>
    <joint name="KUKA_a6_joint">
      <hardwareInterface>hardware_interface/PositionJointInterface</hardwareInterface>
      <hardwareInterface>hardware_interface/EffortJointInterface</hardwareInterface>
    </joint>
    <actuator name="KUKA_a6_motor">
      <hardwareInterface>hardware_interface/PositionJointInterface</hardwareInterface>
      <hardwareInterface>hardware_interface/EffortJointInterface</hardwareInterface>
      <mechanicalReduction>1</mechanicalReduction>
    </actuator>
  </transmission>
  <transmission name="KUKA_a7_trans">
    <type>transmission_interface/SimpleTransmission</type>
    <joint name="KUKA_a7_joint">
      <hardwareInterface>hardware_interface/PositionJointInterface</hardwareInterface>
      <hardwareInterface>hardware_interface/EffortJointInterface</hardwareInterface>
    </joint>
    <actuator name="KUKA_a7_motor">
      <hardwareInterface>hardware_interface/PositionJointInterface</hardwareInterface>
      <hardwareInterface>hardware_interface/EffortJointInterface</hardwareInterface>
      <mechanicalReduction>1</mechanicalReduction>
    </actuator>
  </transmission>
</robot>
